Traceback (most recent call last):
  File "C:\Users\BRIAN\AppData\Local\Programs\Python\Python311\Lib\site-packages\jupyter_cache\executors\utils.py", line 58, in single_nb_execution
    executenb(
  File "C:\Users\BRIAN\AppData\Local\Programs\Python\Python311\Lib\site-packages\nbclient\client.py", line 1319, in execute
    return NotebookClient(nb=nb, resources=resources, km=km, **kwargs).execute()
           ^^^^^^^^^^^^^^^^^^^^^^^^^^^^^^^^^^^^^^^^^^^^^^^^^^^^^^^^^^^^^^^^^^^^^
  File "C:\Users\BRIAN\AppData\Roaming\Python\Python311\site-packages\jupyter_core\utils\__init__.py", line 173, in wrapped
    return loop.run_until_complete(inner)
           ^^^^^^^^^^^^^^^^^^^^^^^^^^^^^^
  File "C:\Users\BRIAN\AppData\Local\Programs\Python\Python311\Lib\asyncio\base_events.py", line 653, in run_until_complete
    return future.result()
           ^^^^^^^^^^^^^^^
  File "C:\Users\BRIAN\AppData\Local\Programs\Python\Python311\Lib\site-packages\nbclient\client.py", line 709, in async_execute
    await self.async_execute_cell(
  File "C:\Users\BRIAN\AppData\Local\Programs\Python\Python311\Lib\site-packages\nbclient\client.py", line 1062, in async_execute_cell
    await self._check_raise_for_error(cell, cell_index, exec_reply)
  File "C:\Users\BRIAN\AppData\Local\Programs\Python\Python311\Lib\site-packages\nbclient\client.py", line 918, in _check_raise_for_error
    raise CellExecutionError.from_cell_and_msg(cell, exec_reply_content)
nbclient.exceptions.CellExecutionError: An error occurred while executing the following cell:
------------------
# menyimpan ke csv
df.to_csv("csv/webmining-journal.csv", index=False)

------------------


[1;31m-----------------------------------------[0m
[1;31mNameError[0mTraceback (most recent call last)
Cell [1;32mIn[4], line 2[0m
[0;32m      1[0m [38;5;66;03m# menyimpan ke csv[39;00m
[1;32m----> 2[0m [43mdf[49m[38;5;241m.[39mto_csv([38;5;124m"[39m[38;5;124mcsv/webmining-journal.csv[39m[38;5;124m"[39m, index[38;5;241m=[39m[38;5;28;01mFalse[39;00m)

[1;31mNameError[0m: name 'df' is not defined

